2024-04-29 10:13:12,307 | ERROR | error in function create_and_get_vendors
Traceback (most recent call last):
  File "/home/nandini/Desktop/fatmug_django/fatmug_django/fatmug_project/fatmug_app/views.py", line 30, in create_and_get_vendors
    vendor = Vendor(
  File "/home/nandini/Desktop/fatmug_django/fatmug_django/venv/lib/python3.8/site-packages/django/db/models/base.py", line 567, in __init__
    raise TypeError(
TypeError: Vendor() got unexpected keyword arguments: 'is_self_created'
2024-04-29 10:22:04,852 | ERROR | error in function create_and_get_vendors
Traceback (most recent call last):
  File "/home/nandini/Desktop/fatmug_django/fatmug_django/venv/lib/python3.8/site-packages/rest_framework/fields.py", line 439, in get_attribute
    return get_attribute(instance, self.source_attrs)
  File "/home/nandini/Desktop/fatmug_django/fatmug_django/venv/lib/python3.8/site-packages/rest_framework/fields.py", line 106, in get_attribute
    instance = getattr(instance, attr)
AttributeError: 'QuerySet' object has no attribute 'name'

During handling of the above exception, another exception occurred:

Traceback (most recent call last):
  File "/home/nandini/Desktop/fatmug_django/fatmug_django/fatmug_project/fatmug_app/views.py", line 46, in create_and_get_vendors
    serializer.data, 200)
  File "/home/nandini/Desktop/fatmug_django/fatmug_django/venv/lib/python3.8/site-packages/rest_framework/serializers.py", line 571, in data
    ret = super().data
  File "/home/nandini/Desktop/fatmug_django/fatmug_django/venv/lib/python3.8/site-packages/rest_framework/serializers.py", line 249, in data
    self._data = self.to_representation(self.instance)
  File "/home/nandini/Desktop/fatmug_django/fatmug_django/venv/lib/python3.8/site-packages/rest_framework/serializers.py", line 525, in to_representation
    attribute = field.get_attribute(instance)
  File "/home/nandini/Desktop/fatmug_django/fatmug_django/venv/lib/python3.8/site-packages/rest_framework/fields.py", line 472, in get_attribute
    raise type(exc)(msg)
AttributeError: Got AttributeError when attempting to get a value for field `name` on serializer `VendorSerializer`.
The serializer field might be named incorrectly and not match any attribute or key on the `QuerySet` instance.
Original exception text was: 'QuerySet' object has no attribute 'name'.
2024-04-29 10:25:50,666 | ERROR | error in function create_and_get_vendors
Traceback (most recent call last):
  File "/home/nandini/Desktop/fatmug_django/fatmug_django/venv/lib/python3.8/site-packages/django/db/backends/utils.py", line 89, in _execute
    return self.cursor.execute(sql, params)
  File "/home/nandini/Desktop/fatmug_django/fatmug_django/venv/lib/python3.8/site-packages/django/db/backends/mysql/base.py", line 75, in execute
    return self.cursor.execute(query, args)
  File "/home/nandini/Desktop/fatmug_django/fatmug_django/venv/lib/python3.8/site-packages/MySQLdb/cursors.py", line 179, in execute
    res = self._query(mogrified_query)
  File "/home/nandini/Desktop/fatmug_django/fatmug_django/venv/lib/python3.8/site-packages/MySQLdb/cursors.py", line 330, in _query
    db.query(q)
  File "/home/nandini/Desktop/fatmug_django/fatmug_django/venv/lib/python3.8/site-packages/MySQLdb/connections.py", line 261, in query
    _mysql.connection.query(self, query)
MySQLdb.IntegrityError: (1062, "Duplicate entry '12345' for key 'vendor.vendor_code'")

The above exception was the direct cause of the following exception:

Traceback (most recent call last):
  File "/home/nandini/Desktop/fatmug_django/fatmug_django/fatmug_project/fatmug_app/views.py", line 40, in create_and_get_vendors
    vendor.save()
  File "/home/nandini/Desktop/fatmug_django/fatmug_django/venv/lib/python3.8/site-packages/django/db/models/base.py", line 814, in save
    self.save_base(
  File "/home/nandini/Desktop/fatmug_django/fatmug_django/venv/lib/python3.8/site-packages/django/db/models/base.py", line 877, in save_base
    updated = self._save_table(
  File "/home/nandini/Desktop/fatmug_django/fatmug_django/venv/lib/python3.8/site-packages/django/db/models/base.py", line 1020, in _save_table
    results = self._do_insert(
  File "/home/nandini/Desktop/fatmug_django/fatmug_django/venv/lib/python3.8/site-packages/django/db/models/base.py", line 1061, in _do_insert
    return manager._insert(
  File "/home/nandini/Desktop/fatmug_django/fatmug_django/venv/lib/python3.8/site-packages/django/db/models/manager.py", line 87, in manager_method
    return getattr(self.get_queryset(), name)(*args, **kwargs)
  File "/home/nandini/Desktop/fatmug_django/fatmug_django/venv/lib/python3.8/site-packages/django/db/models/query.py", line 1805, in _insert
    return query.get_compiler(using=using).execute_sql(returning_fields)
  File "/home/nandini/Desktop/fatmug_django/fatmug_django/venv/lib/python3.8/site-packages/django/db/models/sql/compiler.py", line 1822, in execute_sql
    cursor.execute(sql, params)
  File "/home/nandini/Desktop/fatmug_django/fatmug_django/venv/lib/python3.8/site-packages/django/db/backends/utils.py", line 102, in execute
    return super().execute(sql, params)
  File "/home/nandini/Desktop/fatmug_django/fatmug_django/venv/lib/python3.8/site-packages/django/db/backends/utils.py", line 67, in execute
    return self._execute_with_wrappers(
  File "/home/nandini/Desktop/fatmug_django/fatmug_django/venv/lib/python3.8/site-packages/django/db/backends/utils.py", line 80, in _execute_with_wrappers
    return executor(sql, params, many, context)
  File "/home/nandini/Desktop/fatmug_django/fatmug_django/venv/lib/python3.8/site-packages/django/db/backends/utils.py", line 89, in _execute
    return self.cursor.execute(sql, params)
  File "/home/nandini/Desktop/fatmug_django/fatmug_django/venv/lib/python3.8/site-packages/django/db/utils.py", line 91, in __exit__
    raise dj_exc_value.with_traceback(traceback) from exc_value
  File "/home/nandini/Desktop/fatmug_django/fatmug_django/venv/lib/python3.8/site-packages/django/db/backends/utils.py", line 89, in _execute
    return self.cursor.execute(sql, params)
  File "/home/nandini/Desktop/fatmug_django/fatmug_django/venv/lib/python3.8/site-packages/django/db/backends/mysql/base.py", line 75, in execute
    return self.cursor.execute(query, args)
  File "/home/nandini/Desktop/fatmug_django/fatmug_django/venv/lib/python3.8/site-packages/MySQLdb/cursors.py", line 179, in execute
    res = self._query(mogrified_query)
  File "/home/nandini/Desktop/fatmug_django/fatmug_django/venv/lib/python3.8/site-packages/MySQLdb/cursors.py", line 330, in _query
    db.query(q)
  File "/home/nandini/Desktop/fatmug_django/fatmug_django/venv/lib/python3.8/site-packages/MySQLdb/connections.py", line 261, in query
    _mysql.connection.query(self, query)
django.db.utils.IntegrityError: (1062, "Duplicate entry '12345' for key 'vendor.vendor_code'")
2024-04-29 10:26:25,411 | ERROR | error in function create_and_get_vendors
Traceback (most recent call last):
  File "/home/nandini/Desktop/fatmug_django/fatmug_django/venv/lib/python3.8/site-packages/django/db/backends/utils.py", line 89, in _execute
    return self.cursor.execute(sql, params)
  File "/home/nandini/Desktop/fatmug_django/fatmug_django/venv/lib/python3.8/site-packages/django/db/backends/mysql/base.py", line 75, in execute
    return self.cursor.execute(query, args)
  File "/home/nandini/Desktop/fatmug_django/fatmug_django/venv/lib/python3.8/site-packages/MySQLdb/cursors.py", line 179, in execute
    res = self._query(mogrified_query)
  File "/home/nandini/Desktop/fatmug_django/fatmug_django/venv/lib/python3.8/site-packages/MySQLdb/cursors.py", line 330, in _query
    db.query(q)
  File "/home/nandini/Desktop/fatmug_django/fatmug_django/venv/lib/python3.8/site-packages/MySQLdb/connections.py", line 261, in query
    _mysql.connection.query(self, query)
MySQLdb.IntegrityError: (1062, "Duplicate entry '12345' for key 'vendor.vendor_code'")

The above exception was the direct cause of the following exception:

Traceback (most recent call last):
  File "/home/nandini/Desktop/fatmug_django/fatmug_django/fatmug_project/fatmug_app/views.py", line 40, in create_and_get_vendors
    vendor.save()
  File "/home/nandini/Desktop/fatmug_django/fatmug_django/venv/lib/python3.8/site-packages/django/db/models/base.py", line 814, in save
    self.save_base(
  File "/home/nandini/Desktop/fatmug_django/fatmug_django/venv/lib/python3.8/site-packages/django/db/models/base.py", line 877, in save_base
    updated = self._save_table(
  File "/home/nandini/Desktop/fatmug_django/fatmug_django/venv/lib/python3.8/site-packages/django/db/models/base.py", line 1020, in _save_table
    results = self._do_insert(
  File "/home/nandini/Desktop/fatmug_django/fatmug_django/venv/lib/python3.8/site-packages/django/db/models/base.py", line 1061, in _do_insert
    return manager._insert(
  File "/home/nandini/Desktop/fatmug_django/fatmug_django/venv/lib/python3.8/site-packages/django/db/models/manager.py", line 87, in manager_method
    return getattr(self.get_queryset(), name)(*args, **kwargs)
  File "/home/nandini/Desktop/fatmug_django/fatmug_django/venv/lib/python3.8/site-packages/django/db/models/query.py", line 1805, in _insert
    return query.get_compiler(using=using).execute_sql(returning_fields)
  File "/home/nandini/Desktop/fatmug_django/fatmug_django/venv/lib/python3.8/site-packages/django/db/models/sql/compiler.py", line 1822, in execute_sql
    cursor.execute(sql, params)
  File "/home/nandini/Desktop/fatmug_django/fatmug_django/venv/lib/python3.8/site-packages/django/db/backends/utils.py", line 102, in execute
    return super().execute(sql, params)
  File "/home/nandini/Desktop/fatmug_django/fatmug_django/venv/lib/python3.8/site-packages/django/db/backends/utils.py", line 67, in execute
    return self._execute_with_wrappers(
  File "/home/nandini/Desktop/fatmug_django/fatmug_django/venv/lib/python3.8/site-packages/django/db/backends/utils.py", line 80, in _execute_with_wrappers
    return executor(sql, params, many, context)
  File "/home/nandini/Desktop/fatmug_django/fatmug_django/venv/lib/python3.8/site-packages/django/db/backends/utils.py", line 89, in _execute
    return self.cursor.execute(sql, params)
  File "/home/nandini/Desktop/fatmug_django/fatmug_django/venv/lib/python3.8/site-packages/django/db/utils.py", line 91, in __exit__
    raise dj_exc_value.with_traceback(traceback) from exc_value
  File "/home/nandini/Desktop/fatmug_django/fatmug_django/venv/lib/python3.8/site-packages/django/db/backends/utils.py", line 89, in _execute
    return self.cursor.execute(sql, params)
  File "/home/nandini/Desktop/fatmug_django/fatmug_django/venv/lib/python3.8/site-packages/django/db/backends/mysql/base.py", line 75, in execute
    return self.cursor.execute(query, args)
  File "/home/nandini/Desktop/fatmug_django/fatmug_django/venv/lib/python3.8/site-packages/MySQLdb/cursors.py", line 179, in execute
    res = self._query(mogrified_query)
  File "/home/nandini/Desktop/fatmug_django/fatmug_django/venv/lib/python3.8/site-packages/MySQLdb/cursors.py", line 330, in _query
    db.query(q)
  File "/home/nandini/Desktop/fatmug_django/fatmug_django/venv/lib/python3.8/site-packages/MySQLdb/connections.py", line 261, in query
    _mysql.connection.query(self, query)
django.db.utils.IntegrityError: (1062, "Duplicate entry '12345' for key 'vendor.vendor_code'")
2024-04-29 10:26:34,853 | ERROR | error in function create_and_get_vendors
Traceback (most recent call last):
  File "/home/nandini/Desktop/fatmug_django/fatmug_django/venv/lib/python3.8/site-packages/django/db/backends/utils.py", line 89, in _execute
    return self.cursor.execute(sql, params)
  File "/home/nandini/Desktop/fatmug_django/fatmug_django/venv/lib/python3.8/site-packages/django/db/backends/mysql/base.py", line 75, in execute
    return self.cursor.execute(query, args)
  File "/home/nandini/Desktop/fatmug_django/fatmug_django/venv/lib/python3.8/site-packages/MySQLdb/cursors.py", line 179, in execute
    res = self._query(mogrified_query)
  File "/home/nandini/Desktop/fatmug_django/fatmug_django/venv/lib/python3.8/site-packages/MySQLdb/cursors.py", line 330, in _query
    db.query(q)
  File "/home/nandini/Desktop/fatmug_django/fatmug_django/venv/lib/python3.8/site-packages/MySQLdb/connections.py", line 261, in query
    _mysql.connection.query(self, query)
MySQLdb.DataError: (1406, "Data too long for column 'vendor_code' at row 1")

The above exception was the direct cause of the following exception:

Traceback (most recent call last):
  File "/home/nandini/Desktop/fatmug_django/fatmug_django/fatmug_project/fatmug_app/views.py", line 40, in create_and_get_vendors
    vendor.save()
  File "/home/nandini/Desktop/fatmug_django/fatmug_django/venv/lib/python3.8/site-packages/django/db/models/base.py", line 814, in save
    self.save_base(
  File "/home/nandini/Desktop/fatmug_django/fatmug_django/venv/lib/python3.8/site-packages/django/db/models/base.py", line 877, in save_base
    updated = self._save_table(
  File "/home/nandini/Desktop/fatmug_django/fatmug_django/venv/lib/python3.8/site-packages/django/db/models/base.py", line 1020, in _save_table
    results = self._do_insert(
  File "/home/nandini/Desktop/fatmug_django/fatmug_django/venv/lib/python3.8/site-packages/django/db/models/base.py", line 1061, in _do_insert
    return manager._insert(
  File "/home/nandini/Desktop/fatmug_django/fatmug_django/venv/lib/python3.8/site-packages/django/db/models/manager.py", line 87, in manager_method
    return getattr(self.get_queryset(), name)(*args, **kwargs)
  File "/home/nandini/Desktop/fatmug_django/fatmug_django/venv/lib/python3.8/site-packages/django/db/models/query.py", line 1805, in _insert
    return query.get_compiler(using=using).execute_sql(returning_fields)
  File "/home/nandini/Desktop/fatmug_django/fatmug_django/venv/lib/python3.8/site-packages/django/db/models/sql/compiler.py", line 1822, in execute_sql
    cursor.execute(sql, params)
  File "/home/nandini/Desktop/fatmug_django/fatmug_django/venv/lib/python3.8/site-packages/django/db/backends/utils.py", line 102, in execute
    return super().execute(sql, params)
  File "/home/nandini/Desktop/fatmug_django/fatmug_django/venv/lib/python3.8/site-packages/django/db/backends/utils.py", line 67, in execute
    return self._execute_with_wrappers(
  File "/home/nandini/Desktop/fatmug_django/fatmug_django/venv/lib/python3.8/site-packages/django/db/backends/utils.py", line 80, in _execute_with_wrappers
    return executor(sql, params, many, context)
  File "/home/nandini/Desktop/fatmug_django/fatmug_django/venv/lib/python3.8/site-packages/django/db/backends/utils.py", line 89, in _execute
    return self.cursor.execute(sql, params)
  File "/home/nandini/Desktop/fatmug_django/fatmug_django/venv/lib/python3.8/site-packages/django/db/utils.py", line 91, in __exit__
    raise dj_exc_value.with_traceback(traceback) from exc_value
  File "/home/nandini/Desktop/fatmug_django/fatmug_django/venv/lib/python3.8/site-packages/django/db/backends/utils.py", line 89, in _execute
    return self.cursor.execute(sql, params)
  File "/home/nandini/Desktop/fatmug_django/fatmug_django/venv/lib/python3.8/site-packages/django/db/backends/mysql/base.py", line 75, in execute
    return self.cursor.execute(query, args)
  File "/home/nandini/Desktop/fatmug_django/fatmug_django/venv/lib/python3.8/site-packages/MySQLdb/cursors.py", line 179, in execute
    res = self._query(mogrified_query)
  File "/home/nandini/Desktop/fatmug_django/fatmug_django/venv/lib/python3.8/site-packages/MySQLdb/cursors.py", line 330, in _query
    db.query(q)
  File "/home/nandini/Desktop/fatmug_django/fatmug_django/venv/lib/python3.8/site-packages/MySQLdb/connections.py", line 261, in query
    _mysql.connection.query(self, query)
django.db.utils.DataError: (1406, "Data too long for column 'vendor_code' at row 1")
2024-04-29 10:26:42,845 | ERROR | error in function create_and_get_vendors
Traceback (most recent call last):
  File "/home/nandini/Desktop/fatmug_django/fatmug_django/venv/lib/python3.8/site-packages/rest_framework/fields.py", line 439, in get_attribute
    return get_attribute(instance, self.source_attrs)
  File "/home/nandini/Desktop/fatmug_django/fatmug_django/venv/lib/python3.8/site-packages/rest_framework/fields.py", line 106, in get_attribute
    instance = getattr(instance, attr)
AttributeError: 'QuerySet' object has no attribute 'name'

During handling of the above exception, another exception occurred:

Traceback (most recent call last):
  File "/home/nandini/Desktop/fatmug_django/fatmug_django/fatmug_project/fatmug_app/views.py", line 45, in create_and_get_vendors
    serializer.data, 200)
  File "/home/nandini/Desktop/fatmug_django/fatmug_django/venv/lib/python3.8/site-packages/rest_framework/serializers.py", line 571, in data
    ret = super().data
  File "/home/nandini/Desktop/fatmug_django/fatmug_django/venv/lib/python3.8/site-packages/rest_framework/serializers.py", line 249, in data
    self._data = self.to_representation(self.instance)
  File "/home/nandini/Desktop/fatmug_django/fatmug_django/venv/lib/python3.8/site-packages/rest_framework/serializers.py", line 525, in to_representation
    attribute = field.get_attribute(instance)
  File "/home/nandini/Desktop/fatmug_django/fatmug_django/venv/lib/python3.8/site-packages/rest_framework/fields.py", line 472, in get_attribute
    raise type(exc)(msg)
AttributeError: Got AttributeError when attempting to get a value for field `name` on serializer `VendorSerializer`.
The serializer field might be named incorrectly and not match any attribute or key on the `QuerySet` instance.
Original exception text was: 'QuerySet' object has no attribute 'name'.
2024-04-29 10:36:16,929 | ERROR | error in function create_and_get_vendors
Traceback (most recent call last):
  File "/home/nandini/Desktop/fatmug_django/fatmug_django/venv/lib/python3.8/site-packages/rest_framework/fields.py", line 439, in get_attribute
    return get_attribute(instance, self.source_attrs)
  File "/home/nandini/Desktop/fatmug_django/fatmug_django/venv/lib/python3.8/site-packages/rest_framework/fields.py", line 106, in get_attribute
    instance = getattr(instance, attr)
AttributeError: 'QuerySet' object has no attribute 'name'

During handling of the above exception, another exception occurred:

Traceback (most recent call last):
  File "/home/nandini/Desktop/fatmug_django/fatmug_django/fatmug_project/fatmug_app/views.py", line 46, in create_and_get_vendors
    serializer.data, 200)
  File "/home/nandini/Desktop/fatmug_django/fatmug_django/venv/lib/python3.8/site-packages/rest_framework/serializers.py", line 571, in data
    ret = super().data
  File "/home/nandini/Desktop/fatmug_django/fatmug_django/venv/lib/python3.8/site-packages/rest_framework/serializers.py", line 249, in data
    self._data = self.to_representation(self.instance)
  File "/home/nandini/Desktop/fatmug_django/fatmug_django/venv/lib/python3.8/site-packages/rest_framework/serializers.py", line 525, in to_representation
    attribute = field.get_attribute(instance)
  File "/home/nandini/Desktop/fatmug_django/fatmug_django/venv/lib/python3.8/site-packages/rest_framework/fields.py", line 472, in get_attribute
    raise type(exc)(msg)
AttributeError: Got AttributeError when attempting to get a value for field `name` on serializer `VendorSerializer`.
The serializer field might be named incorrectly and not match any attribute or key on the `QuerySet` instance.
Original exception text was: 'QuerySet' object has no attribute 'name'.
2024-04-29 10:38:00,445 | ERROR | error in function create_and_get_vendors
Traceback (most recent call last):
  File "/home/nandini/Desktop/fatmug_django/fatmug_django/venv/lib/python3.8/site-packages/rest_framework/fields.py", line 439, in get_attribute
    return get_attribute(instance, self.source_attrs)
  File "/home/nandini/Desktop/fatmug_django/fatmug_django/venv/lib/python3.8/site-packages/rest_framework/fields.py", line 106, in get_attribute
    instance = getattr(instance, attr)
AttributeError: 'QuerySet' object has no attribute 'name'

During handling of the above exception, another exception occurred:

Traceback (most recent call last):
  File "/home/nandini/Desktop/fatmug_django/fatmug_django/fatmug_project/fatmug_app/views.py", line 46, in create_and_get_vendors
    serializer.data, 200)
  File "/home/nandini/Desktop/fatmug_django/fatmug_django/venv/lib/python3.8/site-packages/rest_framework/serializers.py", line 571, in data
    ret = super().data
  File "/home/nandini/Desktop/fatmug_django/fatmug_django/venv/lib/python3.8/site-packages/rest_framework/serializers.py", line 249, in data
    self._data = self.to_representation(self.instance)
  File "/home/nandini/Desktop/fatmug_django/fatmug_django/venv/lib/python3.8/site-packages/rest_framework/serializers.py", line 525, in to_representation
    attribute = field.get_attribute(instance)
  File "/home/nandini/Desktop/fatmug_django/fatmug_django/venv/lib/python3.8/site-packages/rest_framework/fields.py", line 472, in get_attribute
    raise type(exc)(msg)
AttributeError: Got AttributeError when attempting to get a value for field `name` on serializer `VendorSerializer`.
The serializer field might be named incorrectly and not match any attribute or key on the `QuerySet` instance.
Original exception text was: 'QuerySet' object has no attribute 'name'.
2024-04-29 10:40:55,038 | ERROR | error in function create_and_get_vendors
Traceback (most recent call last):
  File "/home/nandini/Desktop/fatmug_django/fatmug_django/venv/lib/python3.8/site-packages/rest_framework/fields.py", line 439, in get_attribute
    return get_attribute(instance, self.source_attrs)
  File "/home/nandini/Desktop/fatmug_django/fatmug_django/venv/lib/python3.8/site-packages/rest_framework/fields.py", line 106, in get_attribute
    instance = getattr(instance, attr)
AttributeError: 'QuerySet' object has no attribute 'name'

During handling of the above exception, another exception occurred:

Traceback (most recent call last):
  File "/home/nandini/Desktop/fatmug_django/fatmug_django/fatmug_project/fatmug_app/views.py", line 47, in create_and_get_vendors
    serializer.data, 200)
  File "/home/nandini/Desktop/fatmug_django/fatmug_django/venv/lib/python3.8/site-packages/rest_framework/serializers.py", line 571, in data
    ret = super().data
  File "/home/nandini/Desktop/fatmug_django/fatmug_django/venv/lib/python3.8/site-packages/rest_framework/serializers.py", line 249, in data
    self._data = self.to_representation(self.instance)
  File "/home/nandini/Desktop/fatmug_django/fatmug_django/venv/lib/python3.8/site-packages/rest_framework/serializers.py", line 525, in to_representation
    attribute = field.get_attribute(instance)
  File "/home/nandini/Desktop/fatmug_django/fatmug_django/venv/lib/python3.8/site-packages/rest_framework/fields.py", line 472, in get_attribute
    raise type(exc)(msg)
AttributeError: Got AttributeError when attempting to get a value for field `name` on serializer `VendorSerializer`.
The serializer field might be named incorrectly and not match any attribute or key on the `QuerySet` instance.
Original exception text was: 'QuerySet' object has no attribute 'name'.
2024-04-29 10:46:07,474 | ERROR | error in function create_and_get_vendors
Traceback (most recent call last):
  File "/home/nandini/Desktop/fatmug_django/fatmug_django/venv/lib/python3.8/site-packages/rest_framework/fields.py", line 439, in get_attribute
    return get_attribute(instance, self.source_attrs)
  File "/home/nandini/Desktop/fatmug_django/fatmug_django/venv/lib/python3.8/site-packages/rest_framework/fields.py", line 106, in get_attribute
    instance = getattr(instance, attr)
AttributeError: 'QuerySet' object has no attribute 'name'

During handling of the above exception, another exception occurred:

Traceback (most recent call last):
  File "/home/nandini/Desktop/fatmug_django/fatmug_django/fatmug_project/fatmug_app/views.py", line 47, in create_and_get_vendors
    serializer.data, 200)
  File "/home/nandini/Desktop/fatmug_django/fatmug_django/venv/lib/python3.8/site-packages/rest_framework/serializers.py", line 571, in data
    ret = super().data
  File "/home/nandini/Desktop/fatmug_django/fatmug_django/venv/lib/python3.8/site-packages/rest_framework/serializers.py", line 249, in data
    self._data = self.to_representation(self.instance)
  File "/home/nandini/Desktop/fatmug_django/fatmug_django/venv/lib/python3.8/site-packages/rest_framework/serializers.py", line 525, in to_representation
    attribute = field.get_attribute(instance)
  File "/home/nandini/Desktop/fatmug_django/fatmug_django/venv/lib/python3.8/site-packages/rest_framework/fields.py", line 472, in get_attribute
    raise type(exc)(msg)
AttributeError: Got AttributeError when attempting to get a value for field `name` on serializer `VendorSerializer`.
The serializer field might be named incorrectly and not match any attribute or key on the `QuerySet` instance.
Original exception text was: 'QuerySet' object has no attribute 'name'.
2024-04-29 11:34:05,392 | ERROR | error in function get_vendors
Traceback (most recent call last):
  File "/home/nandini/Desktop/fatmug_django/fatmug_django/fatmug_project/fatmug_app/views.py", line 79, in get_vendors
    total_records = len(vender_filtered_data)
UnboundLocalError: local variable 'vender_filtered_data' referenced before assignment
2024-04-29 11:35:08,746 | ERROR | error in function get_vendors
Traceback (most recent call last):
  File "/home/nandini/Desktop/fatmug_django/fatmug_django/fatmug_project/fatmug_app/views.py", line 90, in get_vendors
    vendor_data, limit, current_page)
UnboundLocalError: local variable 'vendor_data' referenced before assignment
2024-04-29 11:42:56,471 | ERROR | error in function get_vendors
Traceback (most recent call last):
  File "/home/nandini/Desktop/fatmug_django/fatmug_django/fatmug_project/fatmug_app/views.py", line 64, in get_vendors
    json_data = request.data
AttributeError: 'WSGIRequest' object has no attribute 'data'
2024-04-30 06:18:37,404 | ERROR | error in function update_and_get_single_vendor
Traceback (most recent call last):
  File "/home/nandini/Desktop/fatmug_django/fatmug_django/fatmug_project/fatmug_app/views.py", line 121, in update_and_get_single_vendor
    update_vendor_obj = UpdateVender(json_data)
TypeError: UpdateVender() takes no arguments
2024-04-30 07:19:16,772 | ERROR | error in function update_and_get_single_vendor
Traceback (most recent call last):
  File "/home/nandini/Desktop/fatmug_django/fatmug_django/fatmug_project/fatmug_app/views.py", line 134, in update_and_get_single_vendor
    response, returned_status = update_vendor_obj.get_single_vendor(vendor_id, json_data)
TypeError: get_single_vendor() takes 2 positional arguments but 3 were given
2024-04-30 07:21:46,008 | ERROR | error in function update_and_get_single_vendor
Traceback (most recent call last):
  File "/home/nandini/Desktop/fatmug_django/fatmug_django/fatmug_project/fatmug_app/views.py", line 137, in update_and_get_single_vendor
    return Response(response_dict, status.HTTP_200_OK)
UnboundLocalError: local variable 'response_dict' referenced before assignment
2024-04-30 07:23:25,131 | ERROR | error in function update_and_get_single_vendor
Traceback (most recent call last):
  File "/home/nandini/Desktop/fatmug_django/fatmug_django/fatmug_project/fatmug_app/views.py", line 134, in update_and_get_single_vendor
    response, returned_status = update_vendor_obj.get_single_vendor(vendor_id)
  File "/home/nandini/Desktop/fatmug_django/fatmug_django/fatmug_project/fatmug_app/vender_updation.py", line 74, in get_single_vendor
    table_vendor_row_obj = Vendor.objects.get(vendor_code=vendor_id)
  File "/home/nandini/Desktop/fatmug_django/fatmug_django/venv/lib/python3.8/site-packages/django/db/models/manager.py", line 87, in manager_method
    return getattr(self.get_queryset(), name)(*args, **kwargs)
  File "/home/nandini/Desktop/fatmug_django/fatmug_django/venv/lib/python3.8/site-packages/django/db/models/query.py", line 637, in get
    raise self.model.DoesNotExist(
fatmug_app.models.Vendor.DoesNotExist: Vendor matching query does not exist.
2024-04-30 07:26:58,833 | ERROR | error in function update_and_get_single_vendor
Traceback (most recent call last):
  File "/home/nandini/Desktop/fatmug_django/fatmug_django/fatmug_project/fatmug_app/views.py", line 134, in update_and_get_single_vendor
    response, returned_status = update_vendor_obj.get_single_vendor(vendor_id)
  File "/home/nandini/Desktop/fatmug_django/fatmug_django/fatmug_project/fatmug_app/vender_updation.py", line 74, in get_single_vendor
    table_vendor_row_obj = Vendor.objects.get(vendor_code=vendor_id)
  File "/home/nandini/Desktop/fatmug_django/fatmug_django/venv/lib/python3.8/site-packages/django/db/models/manager.py", line 87, in manager_method
    return getattr(self.get_queryset(), name)(*args, **kwargs)
  File "/home/nandini/Desktop/fatmug_django/fatmug_django/venv/lib/python3.8/site-packages/django/db/models/query.py", line 637, in get
    raise self.model.DoesNotExist(
fatmug_app.models.Vendor.DoesNotExist: Vendor matching query does not exist.
2024-04-30 07:27:00,647 | ERROR | error in function update_and_get_single_vendor
Traceback (most recent call last):
  File "/home/nandini/Desktop/fatmug_django/fatmug_django/fatmug_project/fatmug_app/views.py", line 134, in update_and_get_single_vendor
    response, returned_status = update_vendor_obj.get_single_vendor(vendor_id)
  File "/home/nandini/Desktop/fatmug_django/fatmug_django/fatmug_project/fatmug_app/vender_updation.py", line 74, in get_single_vendor
    table_vendor_row_obj = Vendor.objects.get(vendor_code=vendor_id)
  File "/home/nandini/Desktop/fatmug_django/fatmug_django/venv/lib/python3.8/site-packages/django/db/models/manager.py", line 87, in manager_method
    return getattr(self.get_queryset(), name)(*args, **kwargs)
  File "/home/nandini/Desktop/fatmug_django/fatmug_django/venv/lib/python3.8/site-packages/django/db/models/query.py", line 637, in get
    raise self.model.DoesNotExist(
fatmug_app.models.Vendor.DoesNotExist: Vendor matching query does not exist.
